
Epoch 1/10
Training:  71%|███████   | 49/69 [00:15<00:06,  3.20it/s, loss=1.6081, acc=0.2076]
Training failed with error: train_rnn_model() missing 1 required positional argument: 'scheduler'
Detailed error traceback:
Traceback (most recent call last):
  File "C:\Users\fabia\AppData\Local\Temp\ipykernel_16576\1543586385.py", line 137, in <module>
    trained_rnn_model, best_rnn_accuracy = train_rnn_model(
                                           ^^^^^^^^^^^^^^^^
TypeError: train_rnn_model() missing 1 required positional argument: 'scheduler'
Model saved in emergency mode

Epoch 1/10
Training: 100%|██████████| 69/69 [00:21<00:00,  3.27it/s, loss=1.6285, acc=0.2152]
Validation: 100%|██████████| 4/4 [00:01<00:00,  2.23it/s]
Validation accuracy improved from 0.0000 to 0.2160
Train Loss: 1.6043, Train Acc: 0.2152
Val Loss: 1.6003, Val Acc: 0.2160

Epoch 2/10
Training: 100%|██████████| 69/69 [00:20<00:00,  3.33it/s, loss=1.5708, acc=0.2237]
Validation: 100%|██████████| 4/4 [00:01<00:00,  2.47it/s]
Validation accuracy improved from 0.2160 to 0.2260
Train Loss: 1.5961, Train Acc: 0.2237
Val Loss: 1.5961, Val Acc: 0.2260

Epoch 3/10
Training: 100%|██████████| 69/69 [00:17<00:00,  3.89it/s, loss=1.5328, acc=0.2280]
Validation: 100%|██████████| 4/4 [00:01<00:00,  2.85it/s]
Train Loss: 1.5887, Train Acc: 0.2280
Val Loss: 1.5923, Val Acc: 0.2180

Epoch 4/10
Training: 100%|██████████| 69/69 [00:17<00:00,  3.96it/s, loss=1.5807, acc=0.2341]
Validation: 100%|██████████| 4/4 [00:01<00:00,  2.85it/s]
Train Loss: 1.5840, Train Acc: 0.2341
Val Loss: 1.5967, Val Acc: 0.2090

Epoch 5/10
Training: 100%|██████████| 69/69 [00:17<00:00,  4.01it/s, loss=1.5930, acc=0.2322]
Validation: 100%|██████████| 4/4 [00:01<00:00,  2.86it/s]
Train Loss: 1.5792, Train Acc: 0.2322
Val Loss: 1.5906, Val Acc: 0.2210

Epoch 6/10
Training: 100%|██████████| 69/69 [00:18<00:00,  3.75it/s, loss=1.5506, acc=0.2428]
Validation: 100%|██████████| 4/4 [00:01<00:00,  2.80it/s]
Train Loss: 1.5745, Train Acc: 0.2428
Val Loss: 1.5938, Val Acc: 0.2180

Epoch 7/10
Training: 100%|██████████| 69/69 [00:17<00:00,  3.97it/s, loss=1.6355, acc=0.2437]
Validation: 100%|██████████| 4/4 [00:01<00:00,  3.14it/s]
Train Loss: 1.5703, Train Acc: 0.2437
Val Loss: 1.5971, Val Acc: 0.2120

Epoch 8/10
Training: 100%|██████████| 69/69 [00:17<00:00,  3.97it/s, loss=1.6008, acc=0.2461]
Validation: 100%|██████████| 4/4 [00:01<00:00,  2.50it/s]
Train Loss: 1.5681, Train Acc: 0.2461
Val Loss: 1.5981, Val Acc: 0.2210

Epoch 9/10
Training:  29%|██▉       | 20/69 [00:05<00:13,  3.63it/s, loss=1.5609, acc=0.2547]
Training failed with error: Tried to step 691 times. The specified number of total steps is 690
Detailed error traceback:
Traceback (most recent call last):
  File "C:\Users\fabia\AppData\Local\Temp\ipykernel_16576\1688373848.py", line 137, in <module>
    trained_rnn_model, best_rnn_accuracy = train_rnn_model(
                                           ^^^^^^^^^^^^^^^^
  File "C:\Users\fabia\AppData\Local\Temp\ipykernel_16576\1688373848.py", line 56, in train_rnn_model
    scheduler.step()
  File "c:\Users\fabia\AppData\Local\Programs\Python\Python312\Lib\site-packages\torch\optim\lr_scheduler.py", line 241, in step
    values = self.get_lr()
             ^^^^^^^^^^^^^
  File "c:\Users\fabia\AppData\Local\Programs\Python\Python312\Lib\site-packages\torch\optim\lr_scheduler.py", line 2153, in get_lr
    raise ValueError(
ValueError: Tried to step 691 times. The specified number of total steps is 690
Model saved in emergency mode
Using device: cuda
QARNNModel(
  (lstm): LSTM(300, 128, num_layers=2, batch_first=True, dropout=0.2, bidirectional=True)
  (classifier): Sequential(
    (0): Linear(in_features=256, out_features=128, bias=True)
    (1): ReLU()
    (2): Dropout(p=0.2, inplace=False)
    (3): Linear(in_features=128, out_features=1, bias=True)
  )
)
